Workbook

Sheet Index
A1: 2025 Upper Deck Skybox — The Boys (Seasons 1 & 2)
A2: Master Checklist (daily-use). Update status cells on any tab: blank=missing, 'Y…'=incoming, anything else=owned.
A4: Quick Snapshot
A5: Chase Slots | B5: Owned | C5: Incoming | D5: % Owned | E5: % Accounted | F5: Points Owned | G5: Weighted % Owned | H5: Weighted % Accounted
A6: =Dashboard!A5 -> 2396 | B6: =Dashboard!B5 -> 1761 | C6: =Dashboard!C5 -> 3 | D6: =Dashboard!F5 -> 0.73497496 | E6: =Dashboard!G5 -> 0.73622705 | F6: =Dashboard!I5 -> 21379 | G6: =Dashboard!L5 -> 0.25722811 | H6: =Dashboard!M5 -> 0.26271462
A8: Go To Tabs | B8: Rarity / odds nugget
A9: Dashboard | B9: Overall progress + rarity-weighted points
A10: Odds & Rarity | B10: Box/case pull chances + expected cases (editable inputs)
A11: Base S1 | B11: 2× Compound V / box. /7s are *rare* (see Odds tab). Enter serials like 12/25.
A12: Base S2 | B12: Same as S1. /82 & /25 are where the chase starts.
A13: Characters | B13: 50-card character base + numbered parallels
A14: Inserts - Story | B14: Quotes / Behind The Boys / In Memory Of (many at 1:5 packs)
A15: Team Ups | B15: Team Ups are very tough (often cited ~1:100 packs).
A16: A View From Home | B16: A View From Home (~1:48 packs) + SPs (see Odds tab).
A17: Retro | B17: Retro inserts + Retro autographs (now together; /1 autos not counted)
A18: Inserts - General | B18: Metal Prints + Most Wanted (combined)
A19: Supes & Supes SPs | B19: Supes Lenticular 1:30; SPs are tough (see Odds tab).
... A23: Action Figures | B23: Original art: base 1:11; variations 1:90 packs
A24: Achievements
A25: Tip: Use filters on each tab to find missing cards quickly.

Sheet Dashboard
A1: Dashboard
A3: Overall Progress (excludes /1s and printing plates from chase totals & points) | Q3: Config (editable)
A4: Chase Slots | B4: Owned | C4: Incoming | D4: Accounted | E4: Missing | F4: % Owned | G4: % Accounted | H4: Points Possible | I4: Points Owned | J4: Points Incoming | K4: Points Accounted | L4: Weighted % Owned | M4: Weighted % Accounted | Q4: Numbered numerator (K) | R4: 1000
A5: =COUNTIF(Data!$H$2:$H$5000,"Y") -> 2396 | B5: =SUMIFS(Data!$L$2:$L$5000,Data!$H$2:$H$5000,"Y") -> 1761 | C5: =SUMIFS(Data!$M$2:$M$5000,Data!$H$2:$H$5000,"Y") -> 3 | D5: =B5+C5 -> 1764 | E5: =A5-D5 -> 632 | F5: =IF(A5=0,0,B5/A5) -> 0.73497496 | G5: =IF(A5=0,0,D5/A5) -> 0.73622705 | H5: =SUMIFS(Data!$J$2:$J$5000,Data!$H$2:$H$5000,"Y") -> 83113 | I5: =SUM(Data!$P$2:$P$5000) -> 21379 | J5: =SUM(Data!$Q$2:$Q$5000) -> 456 | K5: =I5+J5 -> 21835 | L5: =IF(H5=0,0,I5/H5) -> 0.25722811 | M5: =IF(H5=0,0,K5/H5) -> 0.26271462 | Q5: Base (unnumbered) pts | R5: 1
Q6: Red (unnumbered) pts | R6: 2
A7: Collecting Progress by Insert Type (Set Name) | Q7: Gold (ePack craft) pts | R7: 3
A8: Insert Type (Set Name) | B8: Chase Slots | C8: Owned | D8: Incoming | E8: Accounted | F8: Missing | G8: % Owned | H8: % Accounted | I8: Points Possible | J8: Points Owned | K8: Points Incoming | L8: Points Accounted | M8: Weighted % Owned | N8: Weighted % Accounted | Q8: Category | R8: Multiplier
A9: Base S1 | Q9: Base | R9: 1
A10: Base Set - Season 1 | B10: =COUNTIFS(Data!$B$2:$B$5000,$A10,Data!$H$2:$H$5000,"Y") -> 100 | C10: =SUMIFS(Data!$L$2:$L$5000,Data!$B$2:$B$5000,$A10,Data!$H$2:$H$5000,"Y") -> 100 | D10: =SUMIFS(Data!$M$2:$M$5000,Data!$B$2:$B$5000,$A10,Data!$H$2:$H$5000,"Y") -> 0 | E10: =C10+D10 -> 100 | F10: =B10-E10 -> 0 | G10: =IF(B10=0,0,C10/B10) -> 1 | H10: =IF(B10=0,0,E10/B10) -> 1 | I10: =SUMIFS(Data!$J$2:$J$5000,Data!$B$2:$B$5000,$A10,Data!$H$2:$H$5000,"Y") -> 100 | J10: =SUMIFS(Data!$P$2:$P$5000,Data!$B$2:$B$5000,$A10) -> 100 | K10: =SUMIFS(Data!$Q$2:$Q$5000,Data!$B$2:$B$5000,$A10) -> 0 | L10: =J10+K10 -> 100 | M10: =IF(I10=0,0,J10/I10) -> 1 | N10: =IF(I10=0,0,L10/I10) -> 1 | Q10: Insert | R10: 1.2
A11: Red Parallel - Season 1 | B11: =COUNTIFS(Data!$B$2:$B$5000,$A11,Data!$H$2:$H$5000,"Y") -> 100 | C11: =SUMIFS(Data!$L$2:$L$5000,Data!$B$2:$B$5000,$A11,Data!$H$2:$H$5000,"Y") -> 100 | D11: =SUMIFS(Data!$M$2:$M$5000,Data!$B$2:$B$5000,$A11,Data!$H$2:$H$5000,"Y") -> 0 | E11: =C11+D11 -> 100 | F11: =B11-E11 -> 0 | G11: =IF(B11=0,0,C11/B11) -> 1 | H11: =IF(B11=0,0,E11/B11) -> 1 | I11: =SUMIFS(Data!$J$2:$J$5000,Data!$B$2:$B$5000,$A11,Data!$H$2:$H$5000,"Y") -> 200 | J11: =SUMIFS(Data!$P$2:$P$5000,Data!$B$2:$B$5000,$A11) -> 200 | K11: =SUMIFS(Data!$Q$2:$Q$5000,Data!$B$2:$B$5000,$A11) -> 0 | L11: =J11+K11 -> 200 | M11: =IF(I11=0,0,J11/I11) -> 1 | N11: =IF(I11=0,0,L11/I11) -> 1 | Q11: Lenticular/SP | R11: 1.3
A12: Compound V Parallel - Season 1 | B12: =COUNTIFS(Data!$B$2:$B$5000,$A12,Data!$H$2:$H$5000,"Y") -> 100 | C12: =SUMIFS(Data!$L$2:$L$5000,Data!$B$2:$B$5000,$A12,Data!$H$2:$H$5000,"Y") -> 100 | D12: =SUMIFS(Data!$M$2:$M$5000,Data!$B$2:$B$5000,$A12,Data!$H$2:$H$5000,"Y") -> 0 | E12: =C12+D12 -> 100 | F12: =B12-E12 -> 0 | G12: =IF(B12=0,0,C12/B12) -> 1 | H12: =IF(B12=0,0,E12/B12) -> 1 | I12: =SUMIFS(Data!$J$2:$J$5000,Data!$B$2:$B$5000,$A12,Data!$H$2:$H$5000,"Y") -> 300 | J12: =SUMIFS(Data!$P$2:$P$5000,Data!$B$2:$B$5000,$A12) -> 300 | K12: =SUMIFS(Data!$Q$2:$Q$5000,Data!$B$2:$B$5000,$A12) -> 0 | L12: =J12+K12 -> 300 | M12: =IF(I12=0,0,J12/I12) -> 1 | N12: =IF(I12=0,0,L12/I12) -> 1 | Q12: Memorabilia | R12: 1.8
A13: Gold Parallel - Season 1 | B13: =COUNTIFS(Data!$B$2:$B$5000,$A13,Data!$H$2:$H$5000,"Y") -> 100 | C13: =SUMIFS(Data!$L$2:$L$5000,Data!$B$2:$B$5000,$A13,Data!$H$2:$H$5000,"Y") -> 100 | D13: =SUMIFS(Data!$M$2:$M$5000,Data!$B$2:$B$5000,$A13,Data!$H$2:$H$5000,"Y") -> 0 | E13: =C13+D13 -> 100 | F13: =B13-E13 -> 0 | G13: =IF(B13=0,0,C13/B13) -> 1 | H13: =IF(B13=0,0,E13/B13) -> 1 | I13: =SUMIFS(Data!$J$2:$J$5000,Data!$B$2:$B$5000,$A13,Data!$H$2:$H$5000,"Y") -> 300 | J13: =SUMIFS(Data!$P$2:$P$5000,Data!$B$2:$B$5000,$A13) -> 300 | K13: =SUMIFS(Data!$Q$2:$Q$5000,Data!$B$2:$B$5000,$A13) -> 0 | L13: =J13+K13 -> 300 | M13: =IF(I13=0,0,J13/I13) -> 1 | N13: =IF(I13=0,0,L13/I13) -> 1 | Q13: Auto | R13: 2
A14: Floor 82 Parallel - Season 1 | B14: =COUNTIFS(Data!$B$2:$B$5000,$A14,Data!$H$2:$H$5000,"Y") -> 100 | C14: =SUMIFS(Data!$L$2:$L$5000,Data!$B$2:$B$5000,$A14,Data!$H$2:$H$5000,"Y") -> 100 | D14: =SUMIFS(Data!$M$2:$M$5000,Data!$B$2:$B$5000,$A14,Data!$H$2:$H$5000,"Y") -> 0 | E14: =C14+D14 -> 100 | F14: =B14-E14 -> 0 | G14: =IF(B14=0,0,C14/B14) -> 1 | H14: =IF(B14=0,0,E14/B14) -> 1 | I14: =SUMIFS(Data!$J$2:$J$5000,Data!$B$2:$B$5000,$A14,Data!$H$2:$H$5000,"Y") -> 1200 | J14: =SUMIFS(Data!$P$2:$P$5000,Data!$B$2:$B$5000,$A14) -> 1200 | K14: =SUMIFS(Data!$Q$2:$Q$5000,Data!$B$2:$B$5000,$A14) -> 0 | L14: =J14+K14 -> 1200 | M14: =IF(I14=0,0,J14/I14) -> 1 | N14: =IF(I14=0,0,L14/I14) -> 1
A15: Black Parallel - Season 1 | B15: =COUNTIFS(Data!$B$2:$B$5000,$A15,Data!$H$2:$H$5000,"Y") -> 100 | C15: =SUMIFS(Data!$L$2:$L$5000,Data!$B$2:$B$5000,$A15,Data!$H$2:$H$5000,"Y") -> 41 | D15: =SUMIFS(Data!$M$2:$M$5000,Data!$B$2:$B$5000,$A15,Data!$H$2:$H$5000,"Y") -> 0 | E15: =C15+D15 -> 41 | F15: =B15-E15 -> 59 | G15: =IF(B15=0,0,C15/B15) -> 0.41 | H15: =IF(B15=0,0,E15/B15) -> 0.41 | I15: =SUMIFS(Data!$J$2:$J$5000,Data!$B$2:$B$5000,$A15,Data!$H$2:$H$5000,"Y") -> 4000 | J15: =SUMIFS(Data!$P$2:$P$5000,Data!$B$2:$B$5000,$A15) -> 1640 | K15: =SUMIFS(Data!$Q$2:$Q$5000,Data!$B$2:$B$5000,$A15) -> 0 | L15: =J15+K15 -> 1640 | M15: =IF(I15=0,0,J15/I15) -> 0.41 | N15: =IF(I15=0,0,L15/I15) -> 0.41 | Q15: Category | R15: Unnumbered Base Pts
A16: The Seven Parallel - Season 1 | B16: =COUNTIFS(Data!$B$2:$B$5000,$A16,Data!$H$2:$H$5000,"Y") -> 100 | C16: =SUMIFS(Data!$L$2:$L$5000,Data!$B$2:$B$5000,$A16,Data!$H$2:$H$5000,"Y") -> 13 | D16: =SUMIFS(Data!$M$2:$M$5000,Data!$B$2:$B$5000,$A16,Data!$H$2:$H$5000,"Y") -> 0 | E16: =C16+D16 -> 13 | F16: =B16-E16 -> 87 | G16: =IF(B16=0,0,C16/B16) -> 0.13 | H16: =IF(B16=0,0,E16/B16) -> 0.13 | I16: =SUMIFS(Data!$J$2:$J$5000,Data!$B$2:$B$5000,$A16,Data!$H$2:$H$5000,"Y") -> 14300 | J16: =SUMIFS(Data!$P$2:$P$5000,Data!$B$2:$B$5000,$A16) -> 1859 | K16: =SUMIFS(Data!$Q$2:$Q$5000,Data!$B$2:$B$5000,$A16) -> 0 | L16: =J16+K16 -> 1859 | M16: =IF(I16=0,0,J16/I16) -> 0.13 | N16: =IF(I16=0,0,L16/I16) -> 0.13 | Q16: Base | R16: 1
A17: Base S1 TOTAL | B17: =SUM(B10:B16) -> 700 | C17: =SUM(C10:C16) -> 554 | D17: =SUM(D10:D16) -> 0 | E17: =C17+D17 -> 554 | F17: =B17-E17 -> 146 | G17: =IF(B17=0,0,C17/B17) -> 0.79142857 | H17: =IF(B17=0,0,E17/B17) -> 0.79142857 | I17: =SUM(I10:I16) -> 20400 | J17: =SUM(J10:J16) -> 5599 | K17: =SUM(K10:K16) -> 0 | L17: =J17+K17 -> 5599 | M17: =IF(I17=0,0,J17/I17) -> 0.27446078 | N17: =IF(I17=0,0,L17/I17) -> 0.27446078 | Q17: Insert | R17: 5
A19: Base S2 | Q19: Lenticular/SP | R19: 15
A20: Base Set - Season 2 | B20: =COUNTIFS(Data!$B$2:$B$5000,$A20,Data!$H$2:$H$5000,"Y") -> 100 | C20: =SUMIFS(Data!$L$2:$L$5000,Data!$B$2:$B$5000,$A20,Data!$H$2:$H$5000,"Y") -> 100 | D20: =SUMIFS(Data!$M$2:$M$5000,Data!$B$2:$B$5000,$A20,Data!$H$2:$H$5000,"Y") -> 0 | E20: =C20+D20 -> 100 | F20: =B20-E20 -> 0 | G20: =IF(B20=0,0,C20/B20) -> 1 | H20: =IF(B20=0,0,E20/B20) -> 1 | I20: =SUMIFS(Data!$J$2:$J$5000,Data!$B$2:$B$5000,$A20,Data!$H$2:$H$5000,"Y") -> 100 | J20: =SUMIFS(Data!$P$2:$P$5000,Data!$B$2:$B$5000,$A20) -> 100 | K20: =SUMIFS(Data!$Q$2:$Q$5000,Data!$B$2:$B$5000,$A20) -> 0 | L20: =J20+K20 -> 100 | M20: =IF(I20=0,0,J20/I20) -> 1 | N20: =IF(I20=0,0,L20/I20) -> 1 | Q20: Memorabilia | R20: 25
A21: Red Parallel - Season 2 | B21: =COUNTIFS(Data!$B$2:$B$5000,$A21,Data!$H$2:$H$5000,"Y") -> 100 | C21: =SUMIFS(Data!$L$2:$L$5000,Data!$B$2:$B$5000,$A21,Data!$H$2:$H$5000,"Y") -> 100 | D21: =SUMIFS(Data!$M$2:$M$5000,Data!$B$2:$B$5000,$A21,Data!$H$2:$H$5000,"Y") -> 0 | E21: =C21+D21 -> 100 | F21: =B21-E21 -> 0 | G21: =IF(B21=0,0,C21/B21) -> 1 | H21: =IF(B21=0,0,E21/B21) -> 1 | I21: =SUMIFS(Data!$J$2:$J$5000,Data!$B$2:$B$5000,$A21,Data!$H$2:$H$5000,"Y") -> 200 | J21: =SUMIFS(Data!$P$2:$P$5000,Data!$B$2:$B$5000,$A21) -> 200 | K21: =SUMIFS(Data!$Q$2:$Q$5000,Data!$B$2:$B$5000,$A21) -> 0 | L21: =J21+K21 -> 200 | M21: =IF(I21=0,0,J21/I21) -> 1 | N21: =IF(I21=0,0,L21/I21) -> 1 | Q21: Auto | R21: 25
A22: Compound V Parallel - Season 2 | B22: =COUNTIFS(Data!$B$2:$B$5000,$A22,Data!$H$2:$H$5000,"Y") -> 100 | C22: =SUMIFS(Data!$L$2:$L$5000,Data!$B$2:$B$5000,$A22,Data!$H$2:$H$5000,"Y") -> 100 | D22: =SUMIFS(Data!$M$2:$M$5000,Data!$B$2:$B$5000,$A22,Data!$H$2:$H$5000,"Y") -> 0 | E22: =C22+D22 -> 100 | F22: =B22-E22 -> 0 | G22: =IF(B22=0,0,C22/B22) -> 1 | H22: =IF(B22=0,0,E22/B22) -> 1 | I22: =SUMIFS(Data!$J$2:$J$5000,Data!$B$2:$B$5000,$A22,Data!$H$2:$H$5000,"Y") -> 300 | J22: =SUMIFS(Data!$P$2:$P$5000,Data!$B$2:$B$5000,$A22) -> 300 | K22: =SUMIFS(Data!$Q$2:$Q$5000,Data!$B$2:$B$5000,$A22) -> 0 | L22: =J22+K22 -> 300 | M22: =IF(I22=0,0,J22/I22) -> 1 | N22: =IF(I22=0,0,L22/I22) -> 1
A23: Gold Parallel - Season 2 | B23: =COUNTIFS(Data!$B$2:$B$5000,$A23,Data!$H$2:$H$5000,"Y") -> 100 | C23: =SUMIFS(Data!$L$2:$L$5000,Data!$B$2:$B$5000,$A23,Data!$H$2:$H$5000,"Y") -> 100 | D23: =SUMIFS(Data!$M$2:$M$5000,Data!$B$2:$B$5000,$A23,Data!$H$2:$H$5000,"Y") -> 0 | E23: =C23+D23 -> 100 | F23: =B23-E23 -> 0 | G23: =IF(B23=0,0,C23/B23) -> 1 | H23: =IF(B23=0,0,E23/B23) -> 1 | I23: =SUMIFS(Data!$J$2:$J$5000,Data!$B$2:$B$5000,$A23,Data!$H$2:$H$5000,"Y") -> 300 | J23: =SUMIFS(Data!$P$2:$P$5000,Data!$B$2:$B$5000,$A23) -> 300 | K23: =SUMIFS(Data!$Q$2:$Q$5000,Data!$B$2:$B$5000,$A23) -> 0 | L23: =J23+K23 -> 300 | M23: =IF(I23=0,0,J23/I23) -> 1 | N23: =IF(I23=0,0,L23/I23) -> 1 | Q23: Popularity step per tier | R23: 0.1
A24: Floor 82 Parallel - Season 2 | B24: =COUNTIFS(Data!$B$2:$B$5000,$A24,Data!$H$2:$H$5000,"Y") -> 100 | C24: =SUMIFS(Data!$L$2:$L$5000,Data!$B$2:$B$5000,$A24,Data!$H$2:$H$5000,"Y") -> 100 | D24: =SUMIFS(Data!$M$2:$M$5000,Data!$B$2:$B$5000,$A24,Data!$H$2:$H$5000,"Y") -> 0 | E24: =C24+D24 -> 100 | F24: =B24-E24 -> 0 | G24: =IF(B24=0,0,C24/B24) -> 1 | H24: =IF(B24=0,0,E24/B24) -> 1 | I24: =SUMIFS(Data!$J$2:$J$5000,Data!$B$2:$B$5000,$A24,Data!$H$2:$H$5000,"Y") -> 1200 | J24: =SUMIFS(Data!$P$2:$P$5000,Data!$B$2:$B$5000,$A24) -> 1200 | K24: =SUMIFS(Data!$Q$2:$Q$5000,Data!$B$2:$B$5000,$A24) -> 0 | L24: =J24+K24 -> 1200 | M24: =IF(I24=0,0,J24/I24) -> 1 | N24: =IF(I24=0,0,L24/I24) -> 1 | Q24: Max points per card (cap) | R24: 250
A25: Black Parallel - Season 2 | B25: =COUNTIFS(Data!$B$2:$B$5000,$A25,Data!$H$2:$H$5000,"Y") -> 100 | C25: =SUMIFS(Data!$L$2:$L$5000,Data!$B$2:$B$5000,$A25,Data!$H$2:$H$5000,"Y") -> 45 | D25: =SUMIFS(Data!$M$2:$M$5000,Data!$B$2:$B$5000,$A25,Data!$H$2:$H$5000,"Y") -> 0 | E25: =C25+D25 -> 45 | F25: =B25-E25 -> 55 | G25: =IF(B25=0,0,C25/B25) -> 0.45 | H25: =IF(B25=0,0,E25/B25) -> 0.45 | I25: =SUMIFS(Data!$J$2:$J$5000,Data!$B$2:$B$5000,$A25,Data!$H$2:$H$5000,"Y") -> 4000 | J25: =SUMIFS(Data!$P$2:$P$5000,Data!$B$2:$B$5000,$A25) -> 1800 | K25: =SUMIFS(Data!$Q$2:$Q$5000,Data!$B$2:$B$5000,$A25) -> 0 | L25: =J25+K25 -> 1800 | M25: =IF(I25=0,0,J25/I25) -> 0.45 | N25: =IF(I25=0,0,L25/I25) -> 0.45
A26: The Seven Parallel - Season 2 | B26: =COUNTIFS(Data!$B$2:$B$5000,$A26,Data!$H$2:$H$5000,"Y") -> 100 | C26: =SUMIFS(Data!$L$2:$L$5000,Data!$B$2:$B$5000,$A26,Data!$H$2:$H$5000,"Y") -> 14 | D26: =SUMIFS(Data!$M$2:$M$5000,Data!$B$2:$B$5000,$A26,Data!$H$2:$H$5000,"Y") -> 0 | E26: =C26+D26 -> 14 | F26: =B26-E26 -> 86 | G26: =IF(B26=0,0,C26/B26) -> 0.14 | H26: =IF(B26=0,0,E26/B26) -> 0.14 | I26: =SUMIFS(Data!$J$2:$J$5000,Data!$B$2:$B$5000,$A26,Data!$H$2:$H$5000,"Y") -> 14300 | J26: =SUMIFS(Data!$P$2:$P$5000,Data!$B$2:$B$5000,$A26) -> 2002 | K26: =SUMIFS(Data!$Q$2:$Q$5000,Data!$B$2:$B$5000,$A26) -> 0 | L26: =J26+K26 -> 2002 | M26: =IF(I26=0,0,J26/I26) -> 0.14 | N26: =IF(I26=0,0,L26/I26) -> 0.14
A27: Base S2 TOTAL | B27: =SUM(B20:B26) -> 700 | C27: =SUM(C20:C26) -> 559 | D27: =SUM(D20:D26) -> 0 | E27: =C27+D27 -> 559 | F27: =B27-E27 -> 141 | G27: =IF(B27=0,0,C27/B27) -> 0.79857143 | H27: =IF(B27=0,0,E27/B27) -> 0.79857143 | I27: =SUM(I20:I26) -> 20400 | J27: =SUM(J20:J26) -> 5902 | K27: =SUM(K20:K26) -> 0 | L27: =J27+K27 -> 5902 | M27: =IF(I27=0,0,J27/I27) -> 0.28931373 | N27: =IF(I27=0,0,L27/I27) -> 0.28931373 | Q27: Set Name | R27: Points Override | S27: Multiplier
Q28: Team Ups | R28: 10
A29: Characters | B29: =COUNTIFS(Data!$B$2:$B$5000,$A29,Data!$H$2:$H$5000,"Y") -> 50 | C29: =SUMIFS(Data!$L$2:$L$5000,Data!$B$2:$B$5000,$A29,Data!$H$2:$H$5000,"Y") -> 50 | D29: =SUMIFS(Data!$M$2:$M$5000,Data!$B$2:$B$5000,$A29,Data!$H$2:$H$5000,"Y") -> 0 | E29: =C29+D29 -> 50 | F29: =B29-E29 -> 0 | G29: =IF(B29=0,0,C29/B29) -> 1 | H29: =IF(B29=0,0,E29/B29) -> 1 | I29: =SUMIFS(Data!$J$2:$J$5000,Data!$B$2:$B$5000,$A29,Data!$H$2:$H$5000,"Y") -> 50 | J29: =SUMIFS(Data!$P$2:$P$5000,Data!$B$2:$B$5000,$A29) -> 50 | K29: =SUMIFS(Data!$Q$2:$Q$5000,Data!$B$2:$B$5000,$A29) -> 0 | L29: =J29+K29 -> 50 | M29: =IF(I29=0,0,J29/I29) -> 1 | N29: =IF(I29=0,0,L29/I29) -> 1 | Q29: Most Wanted | R29: 60
A30: Characters Red Parallel | B30: =COUNTIFS(Data!$B$2:$B$5000,$A30,Data!$H$2:$H$5000,"Y") -> 50 | C30: =SUMIFS(Data!$L$2:$L$5000,Data!$B$2:$B$5000,$A30,Data!$H$2:$H$5000,"Y") -> 50 | D30: =SUMIFS(Data!$M$2:$M$5000,Data!$B$2:$B$5000,$A30,Data!$H$2:$H$5000,"Y") -> 0 | E30: =C30+D30 -> 50 | F30: =B30-E30 -> 0 | G30: =IF(B30=0,0,C30/B30) -> 1 | H30: =IF(B30=0,0,E30/B30) -> 1 | I30: =SUMIFS(Data!$J$2:$J$5000,Data!$B$2:$B$5000,$A30,Data!$H$2:$H$5000,"Y") -> 100 | J30: =SUMIFS(Data!$P$2:$P$5000,Data!$B$2:$B$5000,$A30) -> 100 | K30: =SUMIFS(Data!$Q$2:$Q$5000,Data!$B$2:$B$5000,$A30) -> 0 | L30: =J30+K30 -> 100 | M30: =IF(I30=0,0,J30/I30) -> 1 | N30: =IF(I30=0,0,L30/I30) -> 1 | Q30: A View From Home SPs | S30: 1.3333333
A31: Characters Compound V Parallel | B31: =COUNTIFS(Data!$B$2:$B$5000,$A31,Data!$H$2:$H$5000,"Y") -> 50 | C31: =SUMIFS(Data!$L$2:$L$5000,Data!$B$2:$B$5000,$A31,Data!$H$2:$H$5000,"Y") -> 50 | D31: =SUMIFS(Data!$M$2:$M$5000,Data!$B$2:$B$5000,$A31,Data!$H$2:$H$5000,"Y") -> 0 | E31: =C31+D31 -> 50 | F31: =B31-E31 -> 0 | G31: =IF(B31=0,0,C31/B31) -> 1 | H31: =IF(B31=0,0,E31/B31) -> 1 | I31: =SUMIFS(Data!$J$2:$J$5000,Data!$B$2:$B$5000,$A31,Data!$H$2:$H$5000,"Y") -> 138 | J31: =SUMIFS(Data!$P$2:$P$5000,Data!$B$2:$B$5000,$A31) -> 138 | K31: =SUMIFS(Data!$Q$2:$Q$5000,Data!$B$2:$B$5000,$A31) -> 0 | L31: =J31+K31 -> 138 | M31: =IF(I31=0,0,J31/I31) -> 1 | N31: =IF(I31=0,0,L31/I31) -> 1 | Q31: Supes | S31: 2
A32: Characters Gold Parallel | B32: =COUNTIFS(Data!$B$2:$B$5000,$A32,Data!$H$2:$H$5000,"Y") -> 50 | C32: =SUMIFS(Data!$L$2:$L$5000,Data!$B$2:$B$5000,$A32,Data!$H$2:$H$5000,"Y") -> 50 | D32: =SUMIFS(Data!$M$2:$M$5000,Data!$B$2:$B$5000,$A32,Data!$H$2:$H$5000,"Y") -> 0 | E32: =C32+D32 -> 50 | F32: =B32-E32 -> 0 | G32: =IF(B32=0,0,C32/B32) -> 1 | H32: =IF(B32=0,0,E32/B32) -> 1 | I32: =SUMIFS(Data!$J$2:$J$5000,Data!$B$2:$B$5000,$A32,Data!$H$2:$H$5000,"Y") -> 156 | J32: =SUMIFS(Data!$P$2:$P$5000,Data!$B$2:$B$5000,$A32) -> 156 | K32: =SUMIFS(Data!$Q$2:$Q$5000,Data!$B$2:$B$5000,$A32) -> 0 | L32: =J32+K32 -> 156 | M32: =IF(I32=0,0,J32/I32) -> 1 | N32: =IF(I32=0,0,L32/I32) -> 1 | Q32: Supes SPs | S32: 2
A33: Characters Floor 82 Parallel | B33: =COUNTIFS(Data!$B$2:$B$5000,$A33,Data!$H$2:$H$5000,"Y") -> 50 | C33: =SUMIFS(Data!$L$2:$L$5000,Data!$B$2:$B$5000,$A33,Data!$H$2:$H$5000,"Y") -> 50 | D33: =SUMIFS(Data!$M$2:$M$5000,Data!$B$2:$B$5000,$A33,Data!$H$2:$H$5000,"Y") -> 0 | E33: =C33+D33 -> 50 | F33: =B33-E33 -> 0 | G33: =IF(B33=0,0,C33/B33) -> 1 | H33: =IF(B33=0,0,E33/B33) -> 1 | I33: =SUMIFS(Data!$J$2:$J$5000,Data!$B$2:$B$5000,$A33,Data!$H$2:$H$5000,"Y") -> 618 | J33: =SUMIFS(Data!$P$2:$P$5000,Data!$B$2:$B$5000,$A33) -> 618 | K33: =SUMIFS(Data!$Q$2:$Q$5000,Data!$B$2:$B$5000,$A33) -> 0 | L33: =J33+K33 -> 618 | M33: =IF(I33=0,0,J33/I33) -> 1 | N33: =IF(I33=0,0,L33/I33) -> 1 | Q33: Action Figures Autographs Variation | S33: 1.5
A34: Characters Black Parallel | B34: =COUNTIFS(Data!$B$2:$B$5000,$A34,Data!$H$2:$H$5000,"Y") -> 50 | C34: =SUMIFS(Data!$L$2:$L$5000,Data!$B$2:$B$5000,$A34,Data!$H$2:$H$5000,"Y") -> 32 | D34: =SUMIFS(Data!$M$2:$M$5000,Data!$B$2:$B$5000,$A34,Data!$H$2:$H$5000,"Y") -> 0 | E34: =C34+D34 -> 32 | F34: =B34-E34 -> 18 | G34: =IF(B34=0,0,C34/B34) -> 0.64 | H34: =IF(B34=0,0,E34/B34) -> 0.64 | I34: =SUMIFS(Data!$J$2:$J$5000,Data!$B$2:$B$5000,$A34,Data!$H$2:$H$5000,"Y") -> 2048 | J34: =SUMIFS(Data!$P$2:$P$5000,Data!$B$2:$B$5000,$A34) -> 1316 | K34: =SUMIFS(Data!$Q$2:$Q$5000,Data!$B$2:$B$5000,$A34) -> 0 | L34: =J34+K34 -> 1316 | M34: =IF(I34=0,0,J34/I34) -> 0.64257812 | N34: =IF(I34=0,0,L34/I34) -> 0.64257812 | Q34: Triple Supes Suits | S34: 3
A35: Characters The Seven Parallel | B35: =COUNTIFS(Data!$B$2:$B$5000,$A35,Data!$H$2:$H$5000,"Y") -> 50 | C35: =SUMIFS(Data!$L$2:$L$5000,Data!$B$2:$B$5000,$A35,Data!$H$2:$H$5000,"Y") -> 8 | D35: =SUMIFS(Data!$M$2:$M$5000,Data!$B$2:$B$5000,$A35,Data!$H$2:$H$5000,"Y") -> 0 | E35: =C35+D35 -> 8 | F35: =B35-E35 -> 42 | G35: =IF(B35=0,0,C35/B35) -> 0.16 | H35: =IF(B35=0,0,E35/B35) -> 0.16 | I35: =SUMIFS(Data!$J$2:$J$5000,Data!$B$2:$B$5000,$A35,Data!$H$2:$H$5000,"Y") -> 7318 | J35: =SUMIFS(Data!$P$2:$P$5000,Data!$B$2:$B$5000,$A35) -> 1060 | K35: =SUMIFS(Data!$Q$2:$Q$5000,Data!$B$2:$B$5000,$A35) -> 0 | L35: =J35+K35 -> 1060 | M35: =IF(I35=0,0,J35/I35) -> 0.14484832 | N35: =IF(I35=0,0,L35/I35) -> 0.14484832 | Q35: Quad Supes Suits | S35: 4
A36: Characters TOTAL | B36: =SUM(B29:B35) -> 350 | C36: =SUM(C29:C35) -> 290 | D36: =SUM(D29:D35) -> 0 | E36: =C36+D36 -> 290 | F36: =B36-E36 -> 60 | G36: =IF(B36=0,0,C36/B36) -> 0.82857143 | H36: =IF(B36=0,0,E36/B36) -> 0.82857143 | I36: =SUM(I29:I35) -> 10428 | J36: =SUM(J29:J35) -> 3438 | K36: =SUM(K29:K35) -> 0 | L36: =J36+K36 -> 3438 | M36: =IF(I36=0,0,J36/I36) -> 0.3296893 | N36: =IF(I36=0,0,L36/I36) -> 0.3296893 | Q36: Dual Supes Suits Gold | S36: 2
Q37: Triple Supes Suits Gold | S37: 3
A38: Inserts - Story | Q38: Quad Supes Suits Gold | S38: 4
A39: Behind The Boys | B39: =COUNTIFS(Data!$B$2:$B$5000,$A39,Data!$H$2:$H$5000,"Y") -> 15 | C39: =SUMIFS(Data!$L$2:$L$5000,Data!$B$2:$B$5000,$A39,Data!$H$2:$H$5000,"Y") -> 15 | D39: =SUMIFS(Data!$M$2:$M$5000,Data!$B$2:$B$5000,$A39,Data!$H$2:$H$5000,"Y") -> 0 | E39: =C39+D39 -> 15 | F39: =B39-E39 -> 0 | G39: =IF(B39=0,0,C39/B39) -> 1 | H39: =IF(B39=0,0,E39/B39) -> 1 | I39: =SUMIFS(Data!$J$2:$J$5000,Data!$B$2:$B$5000,$A39,Data!$H$2:$H$5000,"Y") -> 15 | J39: =SUMIFS(Data!$P$2:$P$5000,Data!$B$2:$B$5000,$A39) -> 15 | K39: =SUMIFS(Data!$Q$2:$Q$5000,Data!$B$2:$B$5000,$A39) -> 0 | L39: =J39+K39 -> 15 | M39: =IF(I39=0,0,J39/I39) -> 1 | N39: =IF(I39=0,0,L39/I39) -> 1 | Q39: Behind The Boys Gold Parallel | S39: 0.78
A40: In Memory Of... | B40: =COUNTIFS(Data!$B$2:$B$5000,$A40,Data!$H$2:$H$5000,"Y") -> 15 | C40: =SUMIFS(Data!$L$2:$L$5000,Data!$B$2:$B$5000,$A40,Data!$H$2:$H$5000,"Y") -> 15 | D40: =SUMIFS(Data!$M$2:$M$5000,Data!$B$2:$B$5000,$A40,Data!$H$2:$H$5000,"Y") -> 0 | E40: =C40+D40 -> 15 | F40: =B40-E40 -> 0 | G40: =IF(B40=0,0,C40/B40) -> 1 | H40: =IF(B40=0,0,E40/B40) -> 1 | I40: =SUMIFS(Data!$J$2:$J$5000,Data!$B$2:$B$5000,$A40,Data!$H$2:$H$5000,"Y") -> 15 | J40: =SUMIFS(Data!$P$2:$P$5000,Data!$B$2:$B$5000,$A40) -> 15 | K40: =SUMIFS(Data!$Q$2:$Q$5000,Data!$B$2:$B$5000,$A40) -> 0 | L40: =J40+K40 -> 15 | M40: =IF(I40=0,0,J40/I40) -> 1 | N40: =IF(I40=0,0,L40/I40) -> 1 | Q40: In Memory Of... Gold Parallel | S40: 0.78
A41: Quotes | B41: =COUNTIFS(Data!$B$2:$B$5000,$A41,Data!$H$2:$H$5000,"Y") -> 15 | C41: =SUMIFS(Data!$L$2:$L$5000,Data!$B$2:$B$5000,$A41,Data!$H$2:$H$5000,"Y") -> 15 | D41: =SUMIFS(Data!$M$2:$M$5000,Data!$B$2:$B$5000,$A41,Data!$H$2:$H$5000,"Y") -> 0 | E41: =C41+D41 -> 15 | F41: =B41-E41 -> 0 | G41: =IF(B41=0,0,C41/B41) -> 1 | H41: =IF(B41=0,0,E41/B41) -> 1 | I41: =SUMIFS(Data!$J$2:$J$5000,Data!$B$2:$B$5000,$A41,Data!$H$2:$H$5000,"Y") -> 15 | J41: =SUMIFS(Data!$P$2:$P$5000,Data!$B$2:$B$5000,$A41) -> 15 | K41: =SUMIFS(Data!$Q$2:$Q$5000,Data!$B$2:$B$5000,$A41) -> 0 | L41: =J41+K41 -> 15 | M41: =IF(I41=0,0,J41/I41) -> 1 | N41: =IF(I41=0,0,L41/I41) -> 1 | Q41: Quotes Gold Parallel | S41: 0.78
A42: Gold Parallels / Inserts | Q42: Behind The Boys | R42: 1
...

Sheet Pop Estimates (Non-#d)
A1: Group | B1: Set Name | C1: Card # | D1: Card Name | E1: Parallel/Variant | F1: Odds Used (1:X) | G1: Odds Source | H1: Set Size | I1: Est Total Packs | J1: Est Pop (Mid) | K1: Est Pop (Low) | L1: Est Pop (High) | M1: Notes | N1: CardKey | O1: EstPopMid
A2: Autos - Multi | B2: Autographs Quads (Inscribed) | C2: AQ-SEVN | D2: Antony Starr as Homelander/Dominique McElligott as Queen Maeve/Nathan Mitchell as Black Noir/Jessie T. Usher as A-Train "The Seven" | E2: Inscribed | F2: 30000 | G2: Official (shared pool) | H2: 2 | I2: ='Odds & Rarity'!$D$13 -> 1026000 | J2: =ROUND((ROUND((I2/30000)*1/3,0)+ROUND((I2/30000)*3/8,0))/2,0) -> 12 | K2: =ROUND((I2/30000)*1/3,0) -> 11 | L2: =ROUND((I2/30000)*3/8,0) -> 13 | M2: Estimated split using SSP range (5:3 to 2:1). Low/High reflect that split; Mid is avg. | N2: =IF($A2="","",$A2&"|"&$B2&"|"&$C2&"|"&$E2) -> Autos - Multi|Autographs Quads (Inscribed)|AQ-SEVN|Inscribed | O2: =IF($A2="","",$J2) -> 12
A3: Autos - Multi | B3: Autographs Quads | C3: AQ-BOYS | D3: Karl Urban as Billy Butcher/Jack Quaid as Hughie Campbell/Tomer Capone as Frenchie/Laz Alonso as Mother's Milk | E3: Base | F3: 30000 | G3: Official (shared pool) | H3: 2 | I3: ='Odds & Rarity'!$D$13 -> 1026000 | J3: =ROUND((ROUND((I3/30000)*5/8,0)+ROUND((I3/30000)*2/3,0))/2,0) -> 22 | K3: =ROUND((I3/30000)*5/8,0) -> 21 | L3: =ROUND((I3/30000)*2/3,0) -> 23 | M3: Estimated split using SSP range (5:3 to 2:1). Low/High reflect that split; Mid is avg. | N3: =IF($A3="","",$A3&"|"&$B3&"|"&$C3&"|"&$E3) -> Autos - Multi|Autographs Quads|AQ-BOYS|Base | O3: =IF($A3="","",$J3) -> 22
A4: Autos - Multi | B4: Autographs Triples | C4: AT-ESS | D4: Giancarlo Esposito as Stan Edgar/Elisabeth Shue as Madelyn Stillwell/Antony Starr as Homelander | E4: Base | F4: 18000 | G4: Official | H4: 2 | I4: ='Odds & Rarity'!$D$13 -> 1026000 | J4: =IF(OR(I4="",F4="",H4=""),"",ROUND(I4/(F4*H4),0)) -> 29 | K4: =J4 -> 29 | L4: =J4 -> 29 | N4: =IF($A4="","",$A4&"|"&$B4&"|"&$C4&"|"&$E4) -> Autos - Multi|Autographs Triples|AT-ESS|Base | O4: =IF($A4="","",$J4) -> 29
A5: Autos - Multi | B5: Autographs Triples | C5: AT-MMF | D5: Erin Moriarty as Starlight/Dominique McElligott as Queen Maeve/Karen Fukuhara as Kimiko | E5: Base | F5: 18000 | G5: Official | H5: 2 | I5: ='Odds & Rarity'!$D$13 -> 1026000 | J5: =IF(OR(I5="",F5="",H5=""),"",ROUND(I5/(F5*H5),0)) -> 29 | K5: =J5 -> 29 | L5: =J5 -> 29 | N5: =IF($A5="","",$A5&"|"&$B5&"|"&$C5&"|"&$E5) -> Autos - Multi|Autographs Triples|AT-MMF|Base | O5: =IF($A5="","",$J5) -> 29
A6: Autos - Multi | B6: Autographs Duals | C6: AD-ES | D6: Antony Starr as Homelander/Chace Crawford as The Deep | E6: Base | F6: 1800 | G6: Official | H6: 12 | I6: ='Odds & Rarity'!$D$13 -> 1026000 | J6: =IF(OR(I6="",F6="",H6=""),"",ROUND(I6/(F6*H6),0)) -> 48 | K6: =J6 -> 48 | L6: =J6 -> 48 | N6: =IF($A6="","",$A6&"|"&$B6&"|"&$C6&"|"&$E6) -> Autos - Multi|Autographs Duals|AD-ES|Base | O6: =IF($A6="","",$J6) -> 48
A7: Autos - Multi | B7: Autographs Duals | C7: AD-FC | D7: Tomer Capone as Frenchie/Karen Fukuhara as Kimiko | E7: Base | F7: 1800 | G7: Official | H7: 12 | I7: ='Odds & Rarity'!$D$13 -> 1026000 | J7: =IF(OR(I7="",F7="",H7=""),"",ROUND(I7/(F7*H7),0)) -> 48 | K7: =J7 -> 48 | L7: =J7 -> 48 | N7: =IF($A7="","",$A7&"|"&$B7&"|"&$C7&"|"&$E7) -> Autos - Multi|Autographs Duals|AD-FC|Base | O7: =IF($A7="","",$J7) -> 48
A8: Autos - Multi | B8: Autographs Duals | C8: AD-JB | D8: Jessie T. Usher as A-Train/Brittany Allen as Popclaw | E8: Base | F8: 1800 | G8: Official | H8: 12 | I8: ='Odds & Rarity'!$D$13 -> 1026000 | J8: =IF(OR(I8="",F8="",H8=""),"",ROUND(I8/(F8*H8),0)) -> 48 | K8: =J8 -> 48 | L8: =J8 -> 48 | N8: =IF($A8="","",$A8&"|"&$B8&"|"&$C8&"|"&$E8) -> Autos - Multi|Autographs Duals|AD-JB|Base | O8: =IF($A8="","",$J8) -> 48
A9: Autos - Multi | B9: Autographs Duals | C9: AD-MM | D9: Erin Moriarty as Starlight/Dominique McElligott as Queen Maeve | E9: Base | F9: 1800 | G9: Official | H9: 12 | I9: ='Odds & Rarity'!$D$13 -> 1026000 | J9: =IF(OR(I9="",F9="",H9=""),"",ROUND(I9/(F9*H9),0)) -> 48 | K9: =J9 -> 48 | L9: =J9 -> 48 | N9: =IF($A9="","",$A9&"|"&$B9&"|"&$C9&"|"&$E9) -> Autos - Multi|Autographs Duals|AD-MM|Base | O9: =IF($A9="","",$J9) -> 48
A10: Autos - Multi | B10: Autographs Duals | C10: AD-MQ | D10: Jack Quaid as Highie Campbell/Erin Moriarty as Starlight | E10: Base | F10: 1800 | G10: Official | H10: 12 | I10: ='Odds & Rarity'!$D$13 -> 1026000 | J10: =IF(OR(I10="",F10="",H10=""),"",ROUND(I10/(F10*H10),0)) -> 48 | K10: =J10 -> 48 | L10: =J10 -> 48 | N10: =IF($A10="","",$A10&"|"&$B10&"|"&$C10&"|"&$E10) -> Autos - Multi|Autographs Duals|AD-MQ|Base | O10: =IF($A10="","",$J10) -> 48
A11: Autos - Multi | B11: Autographs Duals | C11: AD-QH | D11: Jack Quaid as Hughie Campbell/Alex Hassell as Translucent | E11: Base | F11: 1800 | G11: Official | H11: 12 | I11: ='Odds & Rarity'!$D$13 -> 1026000 | J11: =IF(OR(I11="",F11="",H11=""),"",ROUND(I11/(F11*H11),0)) -> 48 | K11: =J11 -> 48 | L11: =J11 -> 48 | N11: =IF($A11="","",$A11&"|"&$B11&"|"&$C11&"|"&$E11) -> Autos - Multi|Autographs Duals|AD-QH|Base | O11: =IF($A11="","",$J11) -> 48
A12: Autos - Multi | B12: Autographs Duals | C12: AD-SM | D12: Antony Starr as Homelander/Dominique McElligott as Queen Maeve | E12: Base | F12: 1800 | G12: Official | H12: 12 | I12: ='Odds & Rarity'!$D$13 -> 1026000 | J12: =IF(OR(I12="",F12="",H12=""),"",ROUND(I12/(F12*H12),0)) -> 48 | K12: =J12 -> 48 | L12: =J12 -> 48 | N12: =IF($A12="","",$A12&"|"&$B12&"|"&$C12&"|"&$E12) -> Autos - Multi|Autographs Duals|AD-SM|Base | O12: =IF($A12="","",$J12) -> 48
A13: Autos - Multi | B13: Autographs Duals | C13: AD-SS | D13: Antony Starr as Homelander/Elisabeth Shue as Madelyn Stillwell | E13: Base | F13: 1800 | G13: Official | H13: 12 | I13: ='Odds & Rarity'!$D$13 -> 1026000 | J13: =IF(OR(I13="",F13="",H13=""),"",ROUND(I13/(F13*H13),0)) -> 48 | K13: =J13 -> 48 | L13: =J13 -> 48 | N13: =IF($A13="","",$A13&"|"&$B13&"|"&$C13&"|"&$E13) -> Autos - Multi|Autographs Duals|AD-SS|Base | O13: =IF($A13="","",$J13) -> 48
A14: Autos - Multi | B14: Autographs Duals | C14: AD-TA | D14: Laz Alonso as Mother's Milk/Tomer Capone as Frenchie | E14: Base | F14: 1800 | G14: Official | H14: 12 | I14: ='Odds & Rarity'!$D$13 -> 1026000 | J14: =IF(OR(I14="",F14="",H14=""),"",ROUND(I14/(F14*H14),0)) -> 48 | K14: =J14 -> 48 | L14: =J14 -> 48 | N14: =IF($A14="","",$A14&"|"&$B14&"|"&$C14&"|"&$E14) -> Autos - Multi|Autographs Duals|AD-TA|Base | O14: =IF($A14="","",$J14) -> 48
A15: Autos - Multi | B15: Autographs Duals | C15: AD-UQ | D15: Karl Urban as Billy Butcher/Jack Quaid as Hughie Campbell | E15: Base | F15: 1800 | G15: Official | H15: 12 | I15: ='Odds & Rarity'!$D$13 -> 1026000 | J15: =IF(OR(I15="",F15="",H15=""),"",ROUND(I15/(F15*H15),0)) -> 48 | K15: =J15 -> 48 | L15: =J15 -> 48 | N15: =IF($A15="","",$A15&"|"&$B15&"|"&$C15&"|"&$E15) -> Autos - Multi|Autographs Duals|AD-UQ|Base | O15: =IF($A15="","",$J15) -> 48
... A19: Supes Suits | B19: Quad Supes Suits | C19: QSS-2 | D19: Jessie T. Usher as A-Train/Antony Starr as Homelander/Alex Hassell as Translucent/Erin Moriarty as Starlight | E19: Base | F19: 7200 | G19: Official | H19: 2 | I19: ='Odds & Rarity'!$D$13 -> 1026000 | J19: =IF(OR(I19="",F19="",H19=""),"",ROUND(I19/(F19*H19),0)) -> 71 | K19: =J19 -> 71 | L19: =J19 -> 71 | N19: =IF($A19="","",$A19&"|"&$B19&"|"&$C19&"|"&$E19) -> Supes Suits|Quad Supes Suits|QSS-2|Base | O19: =IF($A19="","",$J19) -> 71
A20: Autos - Singles | B20: Autographs | C20: A-AH | D20: Alex Hassell as Translucent | E20: Base | F20: 120 | G20: Assumed | H20: 66 | I20: ='Odds & Rarity'!$D$13 -> 1026000 | J20: =IF(OR(I20="",F20="",H20=""),"",ROUND(I20/(F20*H20),0)) -> 130 | K20: =J20 -> 130 | L20: =J20 -> 130 | M20: Checklist notes odds vary by card; using 1:120 baseline for ballpark. | N20: =IF($A20="","",$A20&"|"&$B20&"|"&$C20&"|"&$E20) -> Autos - Singles|Autographs|A-AH|Base | O20: =IF($A20="","",$J20) -> 130
A21: Autos - Singles | B21: Autographs | C21: A-AL | D21: Brittany Allen as Popclaw "Popclaw" | E21: Base | F21: 120 | G21: Assumed | H21: 66 | I21: ='Odds & Rarity'!$D$13 -> 1026000 | J21: =IF(OR(I21="",F21="",H21=""),"",ROUND(I21/(F21*H21),0)) -> 130 | K21: =J21 -> 130 | L21: =J21 -> 130 | M21: Checklist notes odds vary by card; using 1:120 baseline for ballpark. | N21: =IF($A21="","",$A21&"|"&$B21&"|"&$C21&"|"&$E21) -> Autos - Singles|Autographs|A-AL|Base | O21: =IF($A21="","",$J21) -> 130
A22: Autos - Singles | B22: Autographs | C22: A-AS | D22: Antony Starr as Homelander | E22: Base | F22: 120 | G22: Assumed | H22: 66 | I22: ='Odds & Rarity'!$D$13 -> 1026000 | J22: =IF(OR(I22="",F22="",H22=""),"",ROUND(I22/(F22*H22),0)) -> 130 | K22: =J22 -> 130 | L22: =J22 -> 130 | M22: Checklist notes odds vary by card; using 1:120 baseline for ballpark. | N22: =IF($A22="","",$A22&"|"&$B22&"|"&$C22&"|"&$E22) -> Autos - Singles|Autographs|A-AS|Base | O22: =IF($A22="","",$J22) -> 130
A23: Autos - Singles | B23: Autographs | C23: A-BA | D23: Brittany Allen as Popclaw | E23: Base | F23: 120 | G23: Assumed | H23: 66 | I23: ='Odds & Rarity'!$D$13 -> 1026000 | J23: =IF(OR(I23="",F23="",H23=""),"",ROUND(I23/(F23*H23),0)) -> 130 | K23: =J23 -> 130 | L23: =J23 -> 130 | M23: Checklist notes odds vary by card; using 1:120 baseline for ballpark. | N23: =IF($A23="","",$A23&"|"&$B23&"|"&$C23&"|"&$E23) -> Autos - Singles|Autographs|A-BA|Base | O23: =IF($A23="","",$J23) -> 130
A24: Autos - Singles | B24: Autographs | C24: A-BI | D24: Brittany Allen as Popclaw | E24: Base | F24: 120 | G24: Assumed | H24: 66 | I24: ='Odds & Rarity'!$D$13 -> 1026000 | J24: =IF(OR(I24="",F24="",H24=""),"",ROUND(I24/(F24*H24),0)) -> 130 | K24: =J24 -> 130 | L24: =J24 -> 130 | M24: Checklist notes odds vary by card; using 1:120 baseline for ballpark. | N24: =IF($A24="","",$A24&"|"&$B24&"|"&$C24&"|"&$E24) -> Autos - Singles|Autographs|A-BI|Base | O24: =IF($A24="","",$J24) -> 130
A25: Autos - Singles | B25: Autographs | C25: A-BR | D25: Brittany Allen as Popclaw | E25: Base | F25: 120 | G25: Assumed | H25: 66 | I25: ='Odds & Rarity'!$D$13 -> 1026000 | J25: =IF(OR(I25="",F25="",H25=""),"",ROUND(I25/(F25*H25),0)) -> 130 | K25: =J25 -> 130 | L25: =J25 -> 130 | M25: Checklist notes odds vary by card; using 1:120 baseline for ballpark. | N25: =IF($A25="","",$A25&"|"&$B25&"|"&$C25&"|"&$E25) -> Autos - Singles|Autographs|A-BR|Base | O25: =IF($A25="","",$J25) -> 130
A26: Autos - Singles | B26: Autographs | C26: A-CA | D26: Cameron Crovetti as Ryan | E26: Base | F26: 120 | G26: Assumed | H26: 66 | I26: ='Odds & Rarity'!$D$13 -> 1026000 | J26: =IF(OR(I26="",F26="",H26=""),"",ROUND(I26/(F26*H26),0)) -> 130 | K26: =J26 -> 130 | L26: =J26 -> 130 | M26: Checklist notes odds vary by card; using 1:120 baseline for ballpark. | N26: =IF($A26="","",$A26&"|"&$B26&"|"&$C26&"|"&$E26) -> Autos - Singles|Autographs|A-CA|Base | O26: =IF($A26="","",$J26) -> 130
A27: Autos - Singles | B27: Autographs | C27: A-CC | D27: Chace Crawford as The Deep | E27: Base | F27: 120 | G27: Assumed | H27: 66 | I27: ='Odds & Rarity'!$D$13 -> 1026000 | J27: =IF(OR(I27="",F27="",H27=""),"",ROUND(I27/(F27*H27),0)) -> 130 | K27: =J27 -> 130 | L27: =J27 -> 130 | M27: Checklist notes odds vary by card; using 1:120 baseline for ballpark. | N27: =IF($A27="","",$A27&"|"&$B27&"|"&$C27&"|"&$E27) -> Autos - Singles|Autographs|A-CC|Base | O27: =IF($A27="","",$J27) -> 130
A28: Autos - Singles | B28: Autographs | C28: A-CH | D28: Chace Crawford as The Deep "The Deep" | E28: Inscribed | F28: 120 | G28: Assumed | H28: 66 | I28: ='Odds & Rarity'!$D$13 -> 1026000 | J28: =IF(OR(I28="",F28="",H28=""),"",ROUND(I28/(F28*H28),0)) -> 130 | K28: =J28 -> 130 | L28: =J28 -> 130 | M28: Checklist notes odds vary by card; using 1:120 baseline for ballpark. | N28: =IF($A28="","",$A28&"|"&$B28&"|"&$C28&"|"&$E28) -> Autos - Singles|Autographs|A-CH|Inscribed | O28: =IF($A28="","",$J28) -> 130
A29: Autos - Singles | B29: Autographs | C29: A-CL | D29: Colby Minifie as Ashley Barrett | E29: Base | F29: 120 | G29: Assumed | H29: 66 | I29: ='Odds & Rarity'!$D$13 -> 1026000 | J29: =IF(OR(I29="",F29="",H29=""),"",ROUND(I29/(F29*H29),0)) -> 130 | K29: =J29 -> 130 | L29: =J29 -> 130 | M29: Checklist notes odds vary by card; using 1:120 baseline for ballpark. | N29: =IF($A29="","",$A29&"|"&$B29&"|"&$C29&"|"&$E29) -> Autos - Singles|Autographs|A-CL|Base | O29: =IF($A29="","",$J29) -> 130
A30: Autos - Singles | B30: Autographs | C30: A-CM | D30: Colby Minifie as Ashley Barrett | E30: Base | F30: 120 | G30: Assumed | H30: 66 | I30: ='Odds & Rarity'!$D$13 -> 1026000 | J30: =IF(OR(I30="",F30="",H30=""),"",ROUND(I30/(F30*H30),0)) -> 130 | K30: =J30 -> 130 | L30: =J30 -> 130 | M30: Checklist notes odds vary by card; using 1:120 baseline for ballpark. | N30: =IF($A30="","",$A30&"|"&$B30&"|"&$C30&"|"&$E30) -> Autos - Singles|Autographs|A-CM|Base | O30: =IF($A30="","",$J30) -> 130
A31: Autos - Singles | B31: Autographs | C31: A-CO | D31: Colby Minifie as Ashley Barrett | E31: Base | F31: 120 | G31: Assumed | H31: 66 | I31: ='Odds & Rarity'!$D$13 -> 1026000 | J31: =IF(OR(I31="",F31="",H31=""),"",ROUND(I31/(F31*H31),0)) -> 130 | K31: =J31 -> 130 | L31: =J31 -> 130 | M31: Checklist notes odds vary by card; using 1:120 baseline for ballpark. | N31: =IF($A31="","",$A31&"|"&$B31&"|"&$C31&"|"&$E31) -> Autos - Singles|Autographs|A-CO|Base | O31: =IF($A31="","",$J31) -> 130
... A85: Autos - Singles | B85: Autographs | C85: A-ZZ | D85: Laz Alonso as Mother's Milk | E85: Base | F85: 120 | G85: Assumed | H85: 66 | I85: ='Odds & Rarity'!$D$13 -> 1026000 | J85: =IF(OR(I85="",F85="",H85=""),"",ROUND(I85/(F85*H85),0)) -> 130 | K85: =J85 -> 130 | L85: =J85 -> 130 | M85: Checklist notes odds vary by card; using 1:120 baseline for ballpark. | N85: =IF($A85="","",$A85&"|"&$B85&"|"&$C85&"|"&$E85) -> Autos - Singles|Autographs|A-ZZ|Base | O85: =IF($A85="","",$J85) -> 130
A86: A View From Home | B86: A View From Home SPs | C86: VHSP-1 | D86: A-Train Off the Track | E86: Base | F86: 720 | G86: Official | H86: 10 | I86: ='Odds & Rarity'!$D$13 -> 1026000 | J86: =IF(OR(I86="",F86="",H86=""),"",ROUND(I86/(F86*H86),0)) -> 143 | K86: =J86 -> 143 | L86: =J86 -> 143 | N86: =IF($A86="","",$A86&"|"&$B86&"|"&$C86&"|"&$E86) -> A View From Home|A View From Home SPs|VHSP-1|Base | O86: =IF($A86="","",$J86) -> 143
A87: A View From Home | B87: A View From Home SPs | C87: VHSP-10 | D87: Open the Door | E87: Base | F87: 720 | G87: Official | H87: 10 | I87: ='Odds & Rarity'!$D$13 -> 1026000 | J87: =IF(OR(I87="",F87="",H87=""),"",ROUND(I87/(F87*H87),0)) -> 143 | K87: =J87 -> 143 | L87: =J87 -> 143 | N87: =IF($A87="","",$A87&"|"&$B87&"|"&$C87&"|"&$E87) -> A View From Home|A View From Home SPs|VHSP-10|Base | O87: =IF($A87="","",$J87) -> 143
A88: A View From Home | B88: A View From Home SPs | C88: VHSP-2 | D88: A Farewell to Arms | E88: Base | F88: 720 | G88: Official | H88: 10 | I88: ='Odds & Rarity'!$D$13 -> 1026000 | J88: =IF(OR(I88="",F88="",H88=""),"",ROUND(I88/(F88*H88),0)) -> 143 | K88: =J88 -> 143 | L88: =J88 -> 143 | N88: =IF($A88="","",$A88&"|"&$B88&"|"&$C88&"|"&$E88) -> A View From Home|A View From Home SPs|VHSP-2|Base | O88: =IF($A88="","",$J88) -> 143
A89: A View From Home | B89: A View From Home SPs | C89: VHSP-3 | D89: Bright Future Ahead | E89: Base | F89: 720 | G89: Official | H89: 10 | I89: ='Odds & Rarity'!$D$13 -> 1026000 | J89: =IF(OR(I89="",F89="",H89=""),"",ROUND(I89/(F89*H89),0)) -> 143 | K89: =J89 -> 143 | L89: =J89 -> 143 | N89: =IF($A89="","",$A89&"|"&$B89&"|"&$C89&"|"&$E89) -> A View From Home|A View From Home SPs|VHSP-3|Base | O89: =IF($A89="","",$J89) -> 143
A90: A View From Home | B90: A View From Home SPs | C90: VHSP-4 | D90: Let Me Protect You | E90: Base | F90: 720 | G90: Official | H90: 10 | I90: ='Odds & Rarity'!$D$13 -> 1026000 | J90: =IF(OR(I90="",F90="",H90=""),"",ROUND(I90/(F90*H90),0)) -> 143 | K90: =J90 -> 143 | L90: =J90 -> 143 | N90: =IF($A90="","",$A90&"|"&$B90&"|"&$C90&"|"&$E90) -> A View From Home|A View From Home SPs|VHSP-4|Base | O90: =IF($A90="","",$J90) -> 143
A91: A View From Home | B91: A View From Home SPs | C91: VHSP-5 | D91: Up Close and Personal | E91: Base | F91: 720 | G91: Official | H91: 10 | I91: ='Odds & Rarity'!$D$13 -> 1026000 | J91: =IF(OR(I91="",F91="",H91=""),"",ROUND(I91/(F91*H91),0)) -> 143 | K91: =J91 -> 143 | L91: =J91 -> 143 | N91: =IF($A91="","",$A91&"|"&$B91&"|"&$C91&"|"&$E91) -> A View From Home|A View From Home SPs|VHSP-5|Base | O91: =IF($A91="","",$J91) -> 143
A92: A View From Home | B92: A View From Home SPs | C92: VHSP-6 | D92: No Longer The Seven | E92: Base | F92: 720 | G92: Official | H92: 10 | I92: ='Odds & Rarity'!$D$13 -> 1026000 | J92: =IF(OR(I92="",F92="",H92=""),"",ROUND(I92/(F92*H92),0)) -> 143 | K92: =J92 -> 143 | L92: =J92 -> 143 | N92: =IF($A92="","",$A92&"|"&$B92&"|"&$C92&"|"&$E92) -> A View From Home|A View From Home SPs|VHSP-6|Base | O92: =IF($A92="","",$J92) -> 143
A93: A View From Home | B93: A View From Home SPs | C93: VHSP-7 | D93: Poor Lucy | E93: Base | F93: 720 | G93: Official | H93: 10 | I93: ='Odds & Rarity'!$D$13 -> 1026000 | J93: =IF(OR(I93="",F93="",H93=""),"",ROUND(I93/(F93*H93),0)) -> 143 | K93: =J93 -> 143 | L93: =J93 -> 143 | N93: =IF($A93="","",$A93&"|"&$B93&"|"&$C93&"|"&$E93) -> A View From Home|A View From Home SPs|VHSP-7|Base | O93: =IF($A93="","",$J93) -> 143
A94: A View From Home | B94: A View From Home SPs | C94: VHSP-8 | D94: My Favorite Drink | E94: Base | F94: 720 | G94: Official | H94: 10 | I94: ='Odds & Rarity'!$D$13 -> 1026000 | J94: =IF(OR(I94="",F94="",H94=""),"",ROUND(I94/(F94*H94),0)) -> 143 | K94: =J94 -> 143 | L94: =J94 -> 143 | N94: =IF($A94="","",$A94&"|"&$B94&"|"&$C94&"|"&$E94) -> A View From Home|A View From Home SPs|VHSP-8|Base | O94: =IF($A94="","",$J94) -> 143
A95: A View From Home | B95: A View From Home SPs | C95: VHSP-9 | D95: I'm a Lot Like You | E95: Base | F95: 720 | G95: Official | H95: 10 | I95: ='Odds & Rarity'!$D$13 -> 1026000 | J95: =IF(OR(I95="",F95="",H95=""),"",ROUND(I95/(F95*H95),0)) -> 143 | K95: =J95 -> 143 | L95: =J95 -> 143 | N95: =IF($A95="","",$A95&"|"&$B95&"|"&$C95&"|"&$E95) -> A View From Home|A View From Home SPs|VHSP-9|Base | O95: =IF($A95="","",$J95) -> 143
A96: Lenticular & SP | B96: Supes SPs | C96: S3SP-1 | D96: Homelander | E96: Base | F96: 720 | G96: Official | H96: 10 | I96: ='Odds & Rarity'!$D$13 -> 1026000 | J96: =IF(OR(I96="",F96="",H96=""),"",ROUND(I96/(F96*H96),0)) -> 143 | K96: =J96 -> 143 | L96: =J96 -> 143 | N96: =IF($A96="","",$A96&"|"&$B96&"|"&$C96&"|"&$E96) -> Lenticular & SP|Supes SPs|S3SP-1|Base | O96: =IF($A96="","",$J96) -> 143
...

Sheet Odds & Rarity
A1: Odds & Rarity (Box/Case chances + expected cases)
A3: Inputs (editable)
A4: Packs per Box | B4: 15 | K4: =B12*82 -> 20500 | L4: =IF($K$7=0,"",K4/$K$7) -> 0.71929825
A5: Boxes per Case | B5: 12 | K5: =B12*25 -> 6250 | L5: =IF($K$7=0,"",K5/$K$7) -> 0.21929825
A6: Packs per Case | B6: =B4*B5 -> 180 | K6: =B12*7 -> 1750 | L6: =IF($K$7=0,"",K6/$K$7) -> 0.061403509
A7: Compound V per Box (avg) | B7: 2 | K7: =SUM(K4:K6) -> 28500
A8: Retro/#'d per Case (avg) | B8: 6
A9: Retro odds (packs) (Retro insert) | B9: 180
A10: Retro expected per Case | B10: =B6/B9 -> 1
A11: Estimated #d parallels per Case (excl. Retro) | B11: =MAX(0,B8-B10) -> 5
A12: Base set size (S1+S2+Characters) | B12: 250
A13: Estimated cases produced (derived from total serial-#'d base parallels ÷ est. #'d parallels per case) | B13: =IF($B$11=0,"",$K$7/$B$11) -> 5700 | C13: Estimated total packs produced (derived) | D13: =IF($B$13="","",$B$13*$B$6) -> 1026000
A14: Base Parallels
A15: Compound V is a box hit; other numbered base parallels are estimated from the case-average bucket of “Retro and/or #’d Parallels”.
A16: Parallel | B16: Print Run | C16: Expected hits / Box | D16: Expected hits / Case | E16: % ≥1 / Box | F16: % ≥1 / Case | G16: Exp cases / ANY hit | H16: Exp cases / SPECIFIC card
A17: Compound V | B17: 399 | C17: =B7 -> 2 | D17: =B7*$B$5 -> 24 | E17: =1 -> 1 | F17: =1 -> 1 | G17: =1/(B7*$B$5) -> 0.041666667 | H17: =$B$12/(B7*$B$5) -> 10.416667
A18: Floor 82 | B18: 82 | C18: =$B$11*$L$4/$B$5 -> 0.2997076 | D18: =$B$11*$L$4 -> 3.5964912 | E18: =1-EXP(-C18) -> 0.25896513 | F18: =1-EXP(-D18) -> 0.97258024 | G18: =IF(D18=0,"",1/D18) -> 0.27804878 | H18: =IF(D18=0,"",$B$12/D18) -> 69.512195
A19: Black | B19: 25 | C19: =$B$11*$L$5/$B$5 -> 0.091374269 | D19: =$B$11*$L$5 -> 1.0964912 | E19: =1-EXP(-C19) -> 0.087323939 | F19: =1-EXP(-D19) -> 0.6659589 | G19: =IF(D19=0,"",1/D19) -> 0.912 | H19: =IF(D19=0,"",$B$12/D19) -> 228
A20: The Seven | B20: 7 | C20: =$B$11*$L$6/$B$5 -> 0.025584795 | D20: =$B$11*$L$6 -> 0.30701754 | E20: =1-EXP(-C20) -> 0.025260278 | F20: =1-EXP(-D20) -> 0.26436231 | G20: =IF(D20=0,"",1/D20) -> 3.2571429 | H20: =IF(D20=0,"",$B$12/D20) -> 814.28571
A22: All Inserts & Hits (Official pack odds + Derived odds from print run; derived are NOT official)
A23: Set | B23: Cards in Set | C23: Pack Odds (1:X) | D23: Expected hits / Box | E23: Expected hits / Case | F23: % ≥1 / Box | G23: % ≥1 / Case | H23: Exp cases / ANY hit | I23: Exp cases / SPECIFIC card | J23: Odds Source | K23: Print Run (per card) | L23: Total Copies (set) | M23: Notes
A24: Retro Auto Gold Parallel | B24: =COUNTIF(Data!$B:$B,$A24) -> 14 | C24: =IF($L24=0,"",ROUND($D$13/$L24,0)) -> 73286 | D24: =IF($C24=0,"",$B$4/$C24) -> 0.00020467756 | E24: =IF($C24=0,"",$B$6/$C24) -> 0.0024561308 | F24: =IF($C24=0,"",1-POWER(1-1/$C24,$B$4)) -> 0.00020465802 | G24: =IF($C24=0,"",1-POWER(1-1/$C24,$B$6)) -> 0.0024531337 | H24: =IF($C24=0,"",$C24/$B$6) -> 407.14444 | I24: =IF($C24=0,"",($C24*$B24)/$B$6) -> 5700.0222 | J24: Derived (unofficial) | K24: 1 | L24: =SUMIF(Data!$B:$B,$A24,Data!$F:$F) -> 14
A25: Autographs Duals Gold Parallel (Inscribed) | B25: =COUNTIF(Data!$B:$B,$A25) -> 8 | C25: =IF($L25=0,"",ROUND($D$13/$L25,0)) -> 128250 | D25: =IF($C25=0,"",$B$4/$C25) -> 0.00011695906 | E25: =IF($C25=0,"",$B$6/$C25) -> 0.0014035088 | F25: =IF($C25=0,"",1-POWER(1-1/$C25,$B$4)) -> 0.00011695268 | G25: =IF($C25=0,"",1-POWER(1-1/$C25,$B$6)) -> 0.0014025298 | H25: =IF($C25=0,"",$C25/$B$6) -> 712.5 | I25: =IF($C25=0,"",($C25*$B25)/$B$6) -> 5700 | J25: Derived (unofficial) | K25: 1 | L25: =SUMIF(Data!$B:$B,$A25,Data!$F:$F) -> 8
A26: Autographs Duals Gold Parallel | B26: =COUNTIF(Data!$B:$B,$A26) -> 2 | C26: =IF($L26=0,"",ROUND($D$13/$L26,0)) -> 513000 | D26: =IF($C26=0,"",$B$4/$C26) -> 2.9239766e-05 | E26: =IF($C26=0,"",$B$6/$C26) -> 0.00035087719 | F26: =IF($C26=0,"",1-POWER(1-1/$C26,$B$4)) -> 2.9239367e-05 | G26: =IF($C26=0,"",1-POWER(1-1/$C26,$B$6)) -> 0.00035081598 | H26: =IF($C26=0,"",$C26/$B$6) -> 2850 | I26: =IF($C26=0,"",($C26*$B26)/$B$6) -> 5700 | J26: Derived (unofficial) | K26: 1 | L26: =SUMIF(Data!$B:$B,$A26,Data!$F:$F) -> 2
A27: Autographs Triples Gold Parallel (Inscribed) | B27: =COUNTIF(Data!$B:$B,$A27) -> 2 | C27: =IF($L27=0,"",ROUND($D$13/$L27,0)) -> 513000 | D27: =IF($C27=0,"",$B$4/$C27) -> 2.9239766e-05 | E27: =IF($C27=0,"",$B$6/$C27) -> 0.00035087719 | F27: =IF($C27=0,"",1-POWER(1-1/$C27,$B$4)) -> 2.9239367e-05 | G27: =IF($C27=0,"",1-POWER(1-1/$C27,$B$6)) -> 0.00035081598 | H27: =IF($C27=0,"",$C27/$B$6) -> 2850 | I27: =IF($C27=0,"",($C27*$B27)/$B$6) -> 5700 | J27: Derived (unofficial) | K27: 1 | L27: =SUMIF(Data!$B:$B,$A27,Data!$F:$F) -> 2
A28: Autographs Quads Gold Parallel (Inscribed) | B28: =COUNTIF(Data!$B:$B,$A28) -> 1 | C28: =IF($L28=0,"",ROUND($D$13/$L28,0)) -> 1026000 | D28: =IF($C28=0,"",$B$4/$C28) -> 1.4619883e-05 | E28: =IF($C28=0,"",$B$6/$C28) -> 0.0001754386 | F28: =IF($C28=0,"",1-POWER(1-1/$C28,$B$4)) -> 1.4619783e-05 | G28: =IF($C28=0,"",1-POWER(1-1/$C28,$B$6)) -> 0.00017542329 | H28: =IF($C28=0,"",$C28/$B$6) -> 5700 | I28: =IF($C28=0,"",($C28*$B28)/$B$6) -> 5700 | J28: Derived (unofficial) | K28: 1 | L28: =SUMIF(Data!$B:$B,$A28,Data!$F:$F) -> 1
A29: Autographs Gold Parallel | B29: =COUNTIF(Data!$B:$B,$A29) -> 64 | C29: =IF($L29=0,"",ROUND($D$13/$L29,0)) -> 16031 | D29: =IF($C29=0,"",$B$4/$C29) -> 0.00093568711 | E29: =IF($C29=0,"",$B$6/$C29) -> 0.011228245 | F29: =IF($C29=0,"",1-POWER(1-1/$C29,$B$4)) -> 0.00093527865 | G29: =IF($C29=0,"",1-POWER(1-1/$C29,$B$6)) -> 0.01116579 | H29: =IF($C29=0,"",$C29/$B$6) -> 89.061111 | I29: =IF($C29=0,"",($C29*$B29)/$B$6) -> 5699.9111 | J29: Derived (unofficial) | K29: 1 | L29: =SUMIF(Data!$B:$B,$A29,Data!$F:$F) -> 64
A30: Autographs Quads Red Parallel (Inscribed) | B30: =COUNTIF(Data!$B:$B,$A30) -> 1 | C30: =IF($L30=0,"",ROUND($D$13/$L30,0)) -> 342000 | D30: =IF($C30=0,"",$B$4/$C30) -> 4.3859649e-05 | E30: =IF($C30=0,"",$B$6/$C30) -> 0.00052631579 | F30: =IF($C30=0,"",1-POWER(1-1/$C30,$B$4)) -> 4.3858751e-05 | G30: =IF($C30=0,"",1-POWER(1-1/$C30,$B$6)) -> 0.00052617808 | H30: =IF($C30=0,"",$C30/$B$6) -> 1900 | I30: =IF($C30=0,"",($C30*$B30)/$B$6) -> 1900 | J30: Derived (unofficial) | K30: 3 | L30: =SUMIF(Data!$B:$B,$A30,Data!$F:$F) -> 3
A31: Autographs Printing Plates Parallel (Inscribed) | B31: =COUNTIF(Data!$B:$B,$A31) -> 7 | C31: =IF($L31=0,"",ROUND($D$13/$L31,0)) -> 36643 | D31: =IF($C31=0,"",$B$4/$C31) -> 0.00040935513 | E31: =IF($C31=0,"",$B$6/$C31) -> 0.0049122616 | F31: =IF($C31=0,"",1-POWER(1-1/$C31,$B$4)) -> 0.00040927694 | G31: =IF($C31=0,"",1-POWER(1-1/$C31,$B$6)) -> 0.0049002828 | H31: =IF($C31=0,"",$C31/$B$6) -> 203.57222 | I31: =IF($C31=0,"",($C31*$B31)/$B$6) -> 1425.0056 | J31: Derived (unofficial) | K31: 4 | L31: =SUMIF(Data!$B:$B,$A31,Data!$F:$F) -> 28 | M31: Printing Plates
A32: Printing Plates Parallel - Season 1 | B32: =COUNTIF(Data!$B:$B,$A32) -> 100 | C32: =IF($L32=0,"",ROUND($D$13/$L32,0)) -> 2565 | D32: =IF($C32=0,"",$B$4/$C32) -> 0.0058479532 | E32: =IF($C32=0,"",$B$6/$C32) -> 0.070175439 | F32: =IF($C32=0,"",1-POWER(1-1/$C32,$B$4)) -> 0.0058320208 | G32: =IF($C32=0,"",1-POWER(1-1/$C32,$B$6)) -> 0.067782499 | H32: =IF($C32=0,"",$C32/$B$6) -> 14.25 | I32: =IF($C32=0,"",($C32*$B32)/$B$6) -> 1425 | J32: Derived (unofficial) | K32: 4 | L32: =SUMIF(Data!$B:$B,$A32,Data!$F:$F) -> 400 | M32: Printing Plates
A33: Printing Plates Parallel - Season 2 | B33: =COUNTIF(Data!$B:$B,$A33) -> 100 | C33: =IF($L33=0,"",ROUND($D$13/$L33,0)) -> 2565 | D33: =IF($C33=0,"",$B$4/$C33) -> 0.0058479532 | E33: =IF($C33=0,"",$B$6/$C33) -> 0.070175439 | F33: =IF($C33=0,"",1-POWER(1-1/$C33,$B$4)) -> 0.0058320208 | G33: =IF($C33=0,"",1-POWER(1-1/$C33,$B$6)) -> 0.067782499 | H33: =IF($C33=0,"",$C33/$B$6) -> 14.25 | I33: =IF($C33=0,"",($C33*$B33)/$B$6) -> 1425 | J33: Derived (unofficial) | K33: 4 | L33: =SUMIF(Data!$B:$B,$A33,Data!$F:$F) -> 400 | M33: Printing Plates
A34: Autographs Printing Plates Parallel | B34: =COUNTIF(Data!$B:$B,$A34) -> 57 | C34: =IF($L34=0,"",ROUND($D$13/$L34,0)) -> 4500 | D34: =IF($C34=0,"",$B$4/$C34) -> 0.0033333333 | E34: =IF($C34=0,"",$B$6/$C34) -> 0.04 | F34: =IF($C34=0,"",1-POWER(1-1/$C34,$B$4)) -> 0.0033281531 | G34: =IF($C34=0,"",1-POWER(1-1/$C34,$B$6)) -> 0.039214832 | H34: =IF($C34=0,"",$C34/$B$6) -> 25 | I34: =IF($C34=0,"",($C34*$B34)/$B$6) -> 1425 | J34: Derived (unofficial) | K34: 4 | L34: =SUMIF(Data!$B:$B,$A34,Data!$F:$F) -> 228 | M34: Printing Plates
A35: Characters Printing Plates Parallel | B35: =COUNTIF(Data!$B:$B,$A35) -> 50 | C35: =IF($L35=0,"",ROUND($D$13/$L35,0)) -> 5130 | D35: =IF($C35=0,"",$B$4/$C35) -> 0.0029239766 | E35: =IF($C35=0,"",$B$6/$C35) -> 0.035087719 | F35: =IF($C35=0,"",1-POWER(1-1/$C35,$B$4)) -> 0.0029199901 | G35: =IF($C35=0,"",1-POWER(1-1/$C35,$B$6)) -> 0.034482585 | H35: =IF($C35=0,"",$C35/$B$6) -> 28.5 | I35: =IF($C35=0,"",($C35*$B35)/$B$6) -> 1425 | J35: Derived (unofficial) | K35: 4 | L35: =SUMIF(Data!$B:$B,$A35,Data!$F:$F) -> 200 | M35: Printing Plates
A36: In Memory Of... Printing Plates Parallel | B36: =COUNTIF(Data!$B:$B,$A36) -> 15 | C36: =IF($L36=0,"",ROUND($D$13/$L36,0)) -> 17100 | D36: =IF($C36=0,"",$B$4/$C36) -> 0.00087719298 | E36: =IF($C36=0,"",$B$6/$C36) -> 0.010526316 | F36: =IF($C36=0,"",1-POWER(1-1/$C36,$B$4)) -> 0.00087683399 | G36: =IF($C36=0,"",1-POWER(1-1/$C36,$B$6)) -> 0.010471413 | H36: =IF($C36=0,"",$C36/$B$6) -> 95 | I36: =IF($C36=0,"",($C36*$B36)/$B$6) -> 1425 | J36: Derived (unofficial) | K36: 4 | L36: =SUMIF(Data!$B:$B,$A36,Data!$F:$F) -> 60 | M36: Printing Plates
A37: Autographs Duals Printing Plates Parallel | B37: =COUNTIF(Data!$B:$B,$A37) -> 10 | C37: =IF($L37=0,"",ROUND($D$13/$L37,0)) -> 25650 | D37: =IF($C37=0,"",$B$4/$C37) -> 0.00058479532 | E37: =IF($C37=0,"",$B$6/$C37) -> 0.0070175439 | F37: =IF($C37=0,"",1-POWER(1-1/$C37,$B$4)) -> 0.00058463576 | G37: =IF($C37=0,"",1-POWER(1-1/$C37,$B$6)) -> 0.0069931142 | H37: =IF($C37=0,"",$C37/$B$6) -> 142.5 | I37: =IF($C37=0,"",($C37*$B37)/$B$6) -> 1425 | J37: Derived (unofficial) | K37: 4 | L37: =SUMIF(Data!$B:$B,$A37,Data!$F:$F) -> 40 | M37: Printing Plates
A38: Autographs Triples Printing Plates Parallel | B38: =COUNTIF(Data!$B:$B,$A38) -> 2 | C38: =IF($L38=0,"",ROUND($D$13/$L38,0)) -> 128250 | D38: =IF($C38=0,"",$B$4/$C38) -> 0.00011695906 | E38: =IF($C38=0,"",$B$6/$C38) -> 0.0014035088 | F38: =IF($C38=0,"",1-POWER(1-1/$C38,$B$4)) -> 0.00011695268 | G38: =IF($C38=0,"",1-POWER(1-1/$C38,$B$6)) -> 0.0014025298 | H38: =IF($C38=0,"",$C38/$B$6) -> 712.5 | I38: =IF($C38=0,"",($C38*$B38)/$B$6) -> 1425 | J38: Derived (unofficial) | K38: 4 | L38: =SUMIF(Data!$B:$B,$A38,Data!$F:$F) -> 8 | M38: Printing Plates
A39: Autographs Quads Printing Plates Parallel | B39: =COUNTIF(Data!$B:$B,$A39) -> 1 | C39: =IF($L39=0,"",ROUND($D$13/$L39,0)) -> 256500 | D39: =IF($C39=0,"",$B$4/$C39) -> 5.8479532e-05 | E39: =IF($C39=0,"",$B$6/$C39) -> 0.00070175439 | F39: =IF($C39=0,"",1-POWER(1-1/$C39,$B$4)) -> 5.8477936e-05 | G39: =IF($C39=0,"",1-POWER(1-1/$C39,$B$6)) -> 0.00070150958 | H39: =IF($C39=0,"",$C39/$B$6) -> 1425 | I39: =IF($C39=0,"",($C39*$B39)/$B$6) -> 1425 | J39: Derived (unofficial) | K39: 4 | L39: =SUMIF(Data!$B:$B,$A39,Data!$F:$F) -> 4 | M39: Printing Plates
A40: Autographs Triples Red Parallel | B40: =COUNTIF(Data!$B:$B,$A40) -> 2 | C40: =IF($L40=0,"",ROUND($D$13/$L40,0)) -> 102600 | D40: =IF($C40=0,"",$B$4/$C40) -> 0.00014619883 | E40: =IF($C40=0,"",$B$6/$C40) -> 0.001754386 | F40: =IF($C40=0,"",1-POWER(1-1/$C40,$B$4)) -> 0.00014618886 | G40: =IF($C40=0,"",1-POWER(1-1/$C40,$B$6)) -> 0.0017528565 | H40: =IF($C40=0,"",$C40/$B$6) -> 570 | I40: =IF($C40=0,"",($C40*$B40)/$B$6) -> 1140 | J40: Derived (unofficial) | K40: 5 | L40: =SUMIF(Data!$B:$B,$A40,Data!$F:$F) -> 10
A41: The Seven Parallel - Season 1 | B41: =COUNTIF(Data!$B:$B,$A41) -> 100 | C41: =IF($L41=0,"",ROUND($D$13/$L41,0)) -> 1466 | D41: =IF($C41=0,"",$B$4/$C41) -> 0.010231924 | E41: =IF($C41=0,"",$B$6/$C41) -> 0.12278308 | F41: =IF($C41=0,"",1-POWER(1-1/$C41,$B$4)) -> 0.010183211 | G41: =IF($C41=0,"",1-POWER(1-1/$C41,$B$6)) -> 0.11558156 | H41: =IF($C41=0,"",$C41/$B$6) -> 8.1444444 | I41: =IF($C41=0,"",($C41*$B41)/$B$6) -> 814.44444 | J41: Derived (unofficial) | K41: 7 | L41: =SUMIF(Data!$B:$B,$A41,Data!$F:$F) -> 700
A42: The Seven Parallel - Season 2 | B42: =COUNTIF(Data!$B:$B,$A42) -> 100 | C42: =IF($L42=0,"",ROUND($D$13/$L42,0)) -> 1466 | D42: =IF($C42=0,"",$B$4/$C42) -> 0.010231924 | E42: =IF($C42=0,"",$B$6/$C42) -> 0.12278308 | F42: =IF($C42=0,"",1-POWER(1-1/$C42,$B$4)) -> 0.010183211 | G42: =IF($C42=0,"",1-POWER(1-1/$C42,$B$6)) -> 0.11558156 | H42: =IF($C42=0,"",$C42/$B$6) -> 8.1444444 | I42: =IF($C42=0,"",($C42*$B42)/$B$6) -> 814.44444 | J42: Derived (unofficial) | K42: 7 | L42: =SUMIF(Data!$B:$B,$A42,Data!$F:$F) -> 700
...

Sheet Char Popularity
A1: CharacterKey | B1: PopTier (1-5) | C1: PopMultiplier | D1: Notes
A2: A-Train | B2: 4 | C2: =1+(B2-3)*Dashboard!$R$23 -> 1.1 | D2: edit tier if needed
A3: Ashley Barrett | B3: 3 | C3: =1+(B3-3)*Dashboard!$R$23 -> 1 | D3: edit tier if needed
A4: Becca Butcher | B4: 3 | C4: =1+(B4-3)*Dashboard!$R$23 -> 1 | D4: edit tier if needed
A5: Billy Butcher | B5: 5 | C5: =1+(B5-3)*Dashboard!$R$23 -> 1.2 | D5: edit tier if needed
A6: Black Noir | B6: 4 | C6: =1+(B6-3)*Dashboard!$R$23 -> 1.1 | D6: edit tier if needed
A7: Carol | B7: 3 | C7: =1+(B7-3)*Dashboard!$R$23 -> 1 | D7: edit tier if needed
A8: Cherie | B8: 3 | C8: =1+(B8-3)*Dashboard!$R$23 -> 1 | D8: edit tier if needed
A9: Cindy | B9: 3 | C9: =1+(B9-3)*Dashboard!$R$23 -> 1 | D9: edit tier if needed
A10: Donna January | B10: 3 | C10: =1+(B10-3)*Dashboard!$R$23 -> 1 | D10: edit tier if needed
A11: Doppelganger | B11: 3 | C11: =1+(B11-3)*Dashboard!$R$23 -> 1 | D11: edit tier if needed
A12: Eagle the Archer | B12: 3 | C12: =1+(B12-3)*Dashboard!$R$23 -> 1 | D12: edit tier if needed
A13: Elena | B13: 3 | C13: =1+(B13-3)*Dashboard!$R$23 -> 1 | D13: edit tier if needed
... A43: Victoria Neuman | B43: 4 | C43: =1+(B43-3)*Dashboard!$R$23 -> 1.1 | D43: edit tier if needed

Sheet Base S1
A1: Card # | B1: Card Name | C1: Base | D1: Red | E1: Gold (ePack Craft) | F1: Compound V /399 | G1: Floor 82 /82 | H1: Black /25 | I1: The Seven /7 | J1: Printing Plate
A2: 1 | B2: Maeve Saves | C2: h | D2: h | E2: C | F2: C | G2: V 68/82
A3: 2 | B3: Awww, How Cute! | C3: h | D3: h | E3: C | F3: V | G3: V 66/82
A4: 3 | B4: Lend Me a Hand? | C4: h | D4: h | E4: C | F4: C | G4: C 54/82
A5: 4 | B5: New York, New York | C5: h | D5: h | E5: C | F5: V | G5: C 18/82
A6: 5 | B6: You're on in Five! | C6: h | D6: h | E6: C | F6: V | G6: C 47/82
A7: 6 | B7: Get Them That Got Your Girl | C7: h | D7: h | E7: C | F7: V | G7: C 73/82
A8: 7 | B8: For Supes' Eyes Only | C8: h | D8: h | E8: C | F8: V | G8: C 74/82 | I8: C 1/7
A9: 8 | B9: Watch and Learn | C9: h | D9: h | E9: C | F9: C | G9: C 22/82
A10: 9 | B10: Meet Cute | C10: h | D10: h | E10: C | F10: C | G10: C 32/82 | H10: C 24/25
A11: 10 | B11: Not Admitting Fault | C11: h | D11: h | E11: C | F11: C | G11: V 43/82 | H11: C 16/25
A12: 11 | B12: Now You See Me | C12: h | D12: h | E12: C | F12: V | G12: C '01/82
A13: 12 | B13: Hughie's O Face | C13: h | D13: h | E13: C | F13: V | G13: C 71/82 | I13: C 3/7
A14: 13 | B14: Where's Your Sense of Adventure? | C14: h | D14: h | E14: C | F14: V | G14: C 02/82
A15: 14 | B15: Snitches Get Stitches | C15: h | D15: h | E15: C | F15: V | G15: C 53/82 | J15: V Black C Cyan
A16: 15 | B16: Water-Adjacent Crime | C16: h | D16: h | E16: C | F16: V | G16: V 51/82 | H16: C 19/25
A17: 16 | B17: In Over Your Head | C17: h | D17: h | E17: C | F17: V | G17: C 76/82 | H17: C 15/25 | I17: C 4/7 | J17: V YELLOW
A18: 17 | B18: Blowing Smoke | C18: h | D18: h | E18: C | F18: V | G18: C 58/82 | H18: C 20/25
A19: 18 | B19: Size Matters | C19: h | D19: h | E19: C | F19: V | G19: C '02/82
A20: 19 | B20: We've Got Company | C20: h | D20: h | E20: C | F20: V | G20: V 57/82
A21: 20 | B21: You're the Homelander | C21: h | D21: h | E21: C | F21: V | G21: V 21/82 | H21: C 15/25
A22: 21 | B22: Keep Your Hands Clean | C22: h | D22: h | E22: C | F22: C | G22: C 33/82
A23: 22 | B23: Brothers in Arms | C23: h | D23: h | E23: C | F23: V | G23: C '08/82 | I23: C 7/7
A24: 23 | B24: Unhappy Reunion | C24: h | D24: h | E24: C | F24: C | G24: C 52/82
A25: 24 | B25: You Know the Drill | C25: h | D25: h | E25: C | F25: C | G25: C 25/82
A26: 25 | B26: #Selfie Season | C26: h | D26: h | E26: C | F26: V | G26: C 39/82 | J26: d Magenta
A27: 26 | B27: Almost Caught | C27: h | D27: h | E27: C | F27: V | G27: C 55/82
A28: 27 | B28: Too Fast to Catch | C28: h | D28: h | E28: C | F28: V | G28: C 09/82 | H28: V 18/25
A29: 28 | B29: Terminal Beauty | C29: h | D29: h | E29: C | F29: V | G29: V 66/82 | I29: C 5/7
A30: 29 | B30: Coming for You | C30: h | D30: h | E30: C | F30: V | G30: C 12/82
A31: 30 | B31: The Prisoner | C31: h | D31: h | E31: C | F31: V | G31: C 33/82 | H31: C 14/25
A32: 31 | B32: We're in this Together | C32: h | D32: h | E32: C | F32: V | G32: C '76/82
A33: 32 | B33: Bowling for Supes | C33: h | D33: h | E33: C | F33: V | G33: V 73/82
A34: 33 | B34: Job Well Done | C34: h | D34: h | E34: C | F34: V | G34: V 79/82
A35: 34 | B35: Flight 37 | C35: h | D35: h | E35: C | F35: V | G35: C 42/82
A36: 35 | B36: Detective Butcher | C36: h | D36: h | E36: C | F36: V | G36: C 33/82
A37: 36 | B37: Hidden in Plain Sight | C37: h | D37: h | E37: C | F37: V | G37: C 82/82
A38: 37 | B38: She Ain't One of Us | C38: h | D38: h | E38: C | F38: C | G38: V 50/82
A39: 38 | B39: He's a Friend | C39: h | D39: h | E39: C | F39: V | G39: C 32/82 | I39: C 5/7
A40: 39 | B40: Remember 37 | C40: h | D40: h | E40: C | F40: C | G40: V 13/82 | I40: C 7/7
...

Sheet Base S2
A1: Card # | B1: Card Name | C1: Base | D1: Red | E1: Gold (ePack Craft) | F1: Compound V /399 | G1: Floor 82 /82 | H1: Black /25 | I1: The Seven /7 | J1: Printing Plate
A2: 101 | B2: Terms and Conditions | C2: h | D2: h | E2: C | F2: V | G2: V 46/82 | H2: C 06/25
A3: 102 | B3: Burn in Truth | C3: h | D3: h | E3: C | F3: C | G3: C 29/82
A4: 103 | B4: Out of Sight, Never Out of Mind | C4: h | D4: h | E4: C | F4: C | G4: C
A5: 104 | B5: Never Truly Vanish | C5: h | D5: h | E5: C | F5: C | G5: V 04/82 | H5: C 24/25
A6: 105 | B6: Pressure | C6: h | D6: h | E6: C | F6: C | G6: C '02/82
A7: 106 | B7: Dr. Mother's Milk | C7: h | D7: h | E7: C | F7: C | G7: C 69/82
A8: 107 | B8: Caught In the Act | C8: h | D8: h | E8: C | F8: C | G8: C 15/82
A9: 108 | B9: Filling Ms. Stillwell's Shoes | C9: h | D9: h | E9: C | F9: V | G9: V 25/82 | H9: V 13/25 | I9: C 7/7
A10: 109 | B10: What's Your Poison? | C10: h | D10: h | E10: C | F10: C | G10: V 55/82 | H10: V 22/25
A11: 110 | B11: I Thought We Were Friends | C11: h | D11: h | E11: C | F11: C | G11: V 78/82 | H11: C 20/25
A12: 111 | B12: Stormfront Official | C12: h | D12: h | E12: C | F12: C | G12: C 13/82 | H12: C 18/25
A13: 112 | B13: A Coup From the Inside | C13: h | D13: h | E13: C | F13: V | G13: V '12/82
A14: 113 | B14: No Correct or Incorrect Answer | C14: h | D14: h | E14: C | F14: V | G14: C 48/82 | H14: C 14/25
A15: 114 | B15: What's Missing? | C15: h | D15: h | E15: C | F15: V | G15: C 76/82 | H15: C 17/25
A16: 115 | B16: Time to Realign | C16: h | D16: h | E16: C | F16: C | G16: C 16/82
A17: 116 | B17: Dip in a Little Toe | C17: h | D17: h | E17: C | F17: C | G17: V 35/82 | I17: C 1/7
A18: 117 | B18: Girls Get it Done | C18: h | D18: h | E18: C | F18: C | G18: V 43/82 | H18: C 24/25 | I18: C 1/7
A19: 118 | B19: Here Comes A-train | C19: h | D19: h | E19: C | F19: C | G19: V 29/82 | H19: C 21/25
A20: 119 | B20: Power of Prayer | C20: h | D20: h | E20: C | F20: V | G20: C 67/82
